<?xml version="1.0"?>
<robot xmlns:xacro="http://www.ros.org/wiki/xacro" name="motorcycle">
    <link name="world"></link>

    <joint name="base_joint" type="fixed">
        <origin xyz="0.0 0.0 0.0" rpy="0.0 0.0 0.0"/>
        <parent link="world"/>
        <child link="base_link"/>
    </joint>

    <link name="base_link">
        <inertial>
            <origin xyz="0.0 0.0 0.0" rpy="0.0 0.0 0.0"/>
            <mass value="0.0"/>
            <inertia ixx="0.0" ixy="0.0" ixz="0.0" iyy="0.0" iyz="0.0" izz="0.0"/>
        </inertial>
        <visual name="">
            <origin xyz="0.0 0.0 0.0" rpy="0.0 0.0 0.0"/>
            <geometry>
                <mesh filename="../OBJ/Base.obj" scale=".1 .1 .1"/>
            </geometry>
            <material name="">
                <color rgba="1.0 0.0 0.0 1.0"/>
                <texture filename=""/>
            </material>
        </visual>
        <collision>
            <origin xyz="0.0 0.0 0.0" rpy="0.0 0.0 0.0"/>
            <geometry>
                <mesh filename="../OBJ/Base.obj" scale=".1 .1 .1"/>
            </geometry>
        </collision>
    </link>

    <link name="rear_wheel_link">
        <inertial>
            <origin xyz="0.0 0.0 0.0" rpy="0.0 0.0 0.0"/>
            <mass value="0.0"/>
            <inertia ixx="0.0" ixy="0.0" ixz="0.0" iyy="0.0" iyz="0.0" izz="0.0"/>
        </inertial>
        <visual name="">
            <origin xyz="0.0 0.0 0.0" rpy="0.0 0.0 0.0"/>
            <geometry>
                <mesh filename="../OBJ/Rear_wheel.obj" scale=".1 .1 .1"/>
            </geometry>
            <material name="">
                <color rgba="0.0 0.0 1.0 1.0"/>
                <texture filename=""/>
            </material>
        </visual>
        <collision>
            <origin xyz="0.0 0.0 0.0" rpy="0.0 0.0 0.0"/>
            <geometry>
                <mesh filename="../OBJ/Rear_wheel.obj" scale=".1 .1 .1"/>
            </geometry>
        </collision>
    </link>

    <link name="front_wheel_link">
        <inertial>
            <origin xyz="0.0 0.0 0.0" rpy="0.0 0.0 0.0"/>
            <mass value="0.0"/>
            <inertia ixx="0.0" ixy="0.0" ixz="0.0" iyy="0.0" iyz="0.0" izz="0.0"/>
        </inertial>
        <visual name="">
            <origin xyz="0.0 0.0 0.0" rpy="0.0 0.0 0.0"/>
            <geometry>
                <mesh filename="../OBJ/Front_wheel.obj" scale=".1 .1 .1"/>
            </geometry>
            <material name="">
                <color rgba="1.0 0.0 0.0 1.0"/>
                <texture filename=""/>
            </material>
        </visual>
        <collision>
            <origin xyz="0.0 0.0 0.0" rpy="0.0 0.0 0.0"/>
            <geometry>
                <mesh filename="../OBJ/Front_wheel.obj" scale=".1 .1 .1"/>
            </geometry>
        </collision>
    </link>

    <link name="front_fork_link">
        <inertial>
            <origin xyz="0.0 0.0 0.0" rpy="0.0 0.0 0.0"/>
            <mass value="0.0"/>
            <inertia ixx="0.0" ixy="0.0" ixz="0.0" iyy="0.0" iyz="0.0" izz="0.0"/>
        </inertial>
        <visual name="">
            <origin xyz="0.0 0.0 0.0" rpy="0.0 0.0 0.0"/>
            <geometry>
                <mesh filename="../OBJ/Front_fork.obj" scale=".1 .1 .1"/>
            </geometry>
            <material name="">
                <color rgba="1.0 0.0 0.0 1.0"/>
                <texture filename=""/>
            </material>
        </visual>
        <collision>
            <origin xyz="0.0 0.0 0.0" rpy="0.0 0.0 0.0"/>
            <geometry>
                <mesh filename="../OBJ/Front_fork.obj" scale=".1 .1 .1"/>
            </geometry>
        </collision>
    </link>

    <link name="EV3Core_link">
        <inertial>
            <origin xyz="0.0 0.0 0.0" rpy="0.0 0.0 0.0"/>
            <mass value="0.0"/>
            <inertia ixx="0.0" ixy="0.0" ixz="0.0" iyy="0.0" iyz="0.0" izz="0.0"/>
        </inertial>
        <visual name="">
            <origin xyz="0.0 0.0 0.0" rpy="0.0 0.0 0.0"/>
            <geometry>
                <mesh filename="../OBJ/EV3Core.obj" scale=".1 .1 .1"/>
            </geometry>
            <material name="">
                <color rgba="1.0 0.0 0.0 1.0"/>
                <texture filename=""/>
            </material>
        </visual>
        <collision>
            <origin xyz="0.0 0.0 0.0" rpy="0.0 0.0 0.0"/>
            <geometry>
                <mesh filename="../OBJ/EV3Core.obj" scale=".1 .1 .1"/>
            </geometry>
        </collision>
    </link>

    <link name="right_core_holder_link">
        <inertial>
            <origin xyz="0.0 0.0 0.0" rpy="0.0 0.0 0.0"/>
            <mass value="0.0"/>
            <inertia ixx="0.0" ixy="0.0" ixz="0.0" iyy="0.0" iyz="0.0" izz="0.0"/>
        </inertial>
        <visual name="">
            <origin xyz="0.0 0.0 0.0" rpy="0.0 0.0 0.0"/>
            <geometry>
                <mesh filename="../OBJ/Right_core_holder.obj" scale=".1 .1 .1"/>
            </geometry>
            <material name="">
                <color rgba="1.0 0.0 0.0 1.0"/>
                <texture filename=""/>
            </material>
        </visual>
        <collision>
            <origin xyz="0.0 0.0 0.0" rpy="0.0 0.0 0.0"/>
            <geometry>
                <mesh filename="../OBJ/Right_core_holder.obj" scale=".1 .1 .1"/>
            </geometry>
        </collision>
    </link>

    <link name="left_core_holder_link">
        <inertial>
            <origin xyz="0.0 0.0 0.0" rpy="0.0 0.0 0.0"/>
            <mass value="0.0"/>
            <inertia ixx="0.0" ixy="0.0" ixz="0.0" iyy="0.0" iyz="0.0" izz="0.0"/>
        </inertial>
        <visual name="">
            <origin xyz="0.0 0.0 0.0" rpy="0.0 0.0 0.0"/>
            <geometry>
                <mesh filename="../OBJ/Left_core_holder.obj" scale=".1 .1 .1"/>
            </geometry>
            <material name="">
                <color rgba="1.0 0.0 0.0 1.0"/>
                <texture filename=""/>
            </material>
        </visual>
        <collision>
            <origin xyz="0.0 0.0 0.0" rpy="0.0 0.0 0.0"/>
            <geometry>
                <mesh filename="../OBJ/Left_core_holder.obj" scale=".1 .1 .1"/>
            </geometry>
        </collision>
    </link>

    <link name="right_rack_link">
        <inertial>
            <origin xyz="0.0 0.0 0.0" rpy="0.0 0.0 0.0"/>
            <mass value="0.0"/>
            <inertia ixx="0.0" ixy="0.0" ixz="0.0" iyy="0.0" iyz="0.0" izz="0.0"/>
        </inertial>
        <visual name="">
            <origin xyz="0.0 0.0 0.0" rpy="0.0 0.0 0.0"/>
            <geometry>
                <mesh filename="../OBJ/Right_rack.obj" scale=".1 .1 .1"/>
            </geometry>
            <material name="">
                <color rgba="1.0 0.0 0.0 1.0"/>
                <texture filename=""/>
            </material>
        </visual>
        <collision>
            <origin xyz="0.0 0.0 0.0" rpy="0.0 0.0 0.0"/>
            <geometry>
                <mesh filename="../OBJ/Right_rack.obj" scale=".1 .1 .1"/>
            </geometry>
        </collision>
    </link>

    <link name="left_rack_link">
        <inertial>
            <origin xyz="0.0 0.0 0.0" rpy="0.0 0.0 0.0"/>
            <mass value="0.0"/>
            <inertia ixx="0.0" ixy="0.0" ixz="0.0" iyy="0.0" iyz="0.0" izz="0.0"/>
        </inertial>
        <visual name="">
            <origin xyz="0.0 0.0 0.0" rpy="0.0 0.0 0.0"/>
            <geometry>
                <mesh filename="../OBJ/Left_rack.obj" scale=".1 .1 .1"/>
            </geometry>
            <material name="">
                <color rgba="1.0 0.0 0.0 1.0"/>
                <texture filename=""/>
            </material>
        </visual>
        <collision>
            <origin xyz="0.0 0.0 0.0" rpy="0.0 0.0 0.0"/>
            <geometry>
                <mesh filename="../OBJ/Left_rack.obj" scale=".1 .1 .1"/>
            </geometry>
        </collision>
    </link>

    <joint name="front_wheel_joint" type="continuous">
        <origin xyz="0.0 0.0 0.0" rpy="0.0 0.0 0.0"/>
        <parent link="front_fork_link"/>
        <child link="front_wheel_link"/>
        <axis xyz="1. 0.0 0.0"/>
    </joint>

    <joint name="rear_wheel_joint" type="continuous">
        <origin xyz="0.0 -52 18" rpy="0.0 0.0 0.0"/>
        <parent link="base_link"/>
        <child link="rear_wheel_link"/>
        <axis xyz="1. 0.0 0.0"/>
    </joint>

    <joint name="front_fork_joint" type="revolute">
        <origin xyz="0.0 0 0" rpy="0.0 0.0 0.0"/>
        <parent link="base_link"/>
        <child link="front_fork_link"/>
        <axis xyz="0.0 0.0 1.0"/>
        <limit lower="-0.6" upper="0.6" effort="0.0" velocity="1.0"/>
        
    </joint>

    <joint name="EV3Core_joint" type="revolute">
        <origin xyz="0.0 -15 34" rpy="0.0 0.0 0.0"/>
        <parent link="base_link"/>
        <child link="EV3Core_link"/>
        <axis xyz="0.0 0.9 0.0"/>
        <limit lower="-0.45" upper="0.45" effort="0.0" velocity="1.0"/>
        
    </joint>

</robot>